2024-12-10 20:56:32,623 - APP - app_logger - ERROR - MI ERROR: Excepci�n: {'ret_code': -1, 'ret_txt': 'arqueo_caja.grabar - insert'} - ERROR: 'pyodbc.Row' object has no attribute 'Operaciones' - 'pyodbc.Row' object has no attribute 'Operaciones' - LOCALIZACION: 0 # detalle.Operaciones, - D:\Nube\GitHub\Mallorquina_API\app\services\mallorquina\arqueo_caja.py - 219 - grabar)
2024-12-10 20:56:32,725 - APP - app_logger - ERROR - MI ERROR: GenericException: {'ret_code': -1, 'ret_txt': "Unable to serialize unknown type: <class 'pyodbc.Row'>"} - ERROR: Unable to serialize unknown type: <class 'pyodbc.Row'> - Unable to serialize unknown type: <class 'pyodbc.Row'> - LOCALIZACION: return self.serializer.to_python( - C:\Users\lvicente\AppData\Local\Programs\Python\Python311\Lib\site_packages\pydantic\type_adapter.py - 527 - dump_python)
2024-12-10 20:56:44,515 - APP - app_logger - ERROR - MI ERROR: Excepci�n: {'ret_code': -1, 'ret_txt': 'arqueo_caja.grabar - insert'} - ERROR: 1452 - 1452 (23000): Cannot add or update a child row: a foreign key constraint fails (`mallorquina`.`mll_rec_ventas_medio_pago`, CONSTRAINT `mll_rec_ventas_medio_pago_ibfk_2` FOREIGN KEY (`id_medios_pago`) REFERENCES `mll_mae_medios_pago` (`ID`)) - LOCALIZACION: raise get_mysql_exception( - C:\Users\lvicente\AppData\Local\Programs\Python\Python311\Lib\site_packages\mysql\connector\connection_cext.py - 713 - cmd_query)
2024-12-10 20:56:52,801 - APP - app_logger - ERROR - MI ERROR: Excepci�n: {'ret_code': -1, 'ret_txt': 'arqueo_caja.grabar - insert'} - ERROR: 1452 - 1452 (23000): Cannot add or update a child row: a foreign key constraint fails (`mallorquina`.`mll_rec_ventas_medio_pago`, CONSTRAINT `mll_rec_ventas_medio_pago_ibfk_2` FOREIGN KEY (`id_medios_pago`) REFERENCES `mll_mae_medios_pago` (`ID`)) - LOCALIZACION: raise get_mysql_exception( - C:\Users\lvicente\AppData\Local\Programs\Python\Python311\Lib\site_packages\mysql\connector\connection_cext.py - 713 - cmd_query)
2024-12-10 20:57:25,658 - APP - app_logger - ERROR - MI ERROR: Excepci�n: {'ret_code': -1, 'ret_txt': 'arqueo_caja.grabar - insert'} - ERROR: 1452 - 1452 (23000): Cannot add or update a child row: a foreign key constraint fails (`mallorquina`.`mll_rec_ventas_medio_pago`, CONSTRAINT `mll_rec_ventas_medio_pago_ibfk_2` FOREIGN KEY (`id_medios_pago`) REFERENCES `mll_mae_medios_pago` (`ID`)) - LOCALIZACION: raise get_mysql_exception( - C:\Users\lvicente\AppData\Local\Programs\Python\Python311\Lib\site_packages\mysql\connector\connection_cext.py - 713 - cmd_query)
2024-12-10 20:57:25,765 - APP - app_logger - ERROR - MI ERROR: GenericException: {'ret_code': -1, 'ret_txt': "Unable to serialize unknown type: <class 'pyodbc.Row'>"} - ERROR: Unable to serialize unknown type: <class 'pyodbc.Row'> - Unable to serialize unknown type: <class 'pyodbc.Row'> - LOCALIZACION: return self.serializer.to_python( - C:\Users\lvicente\AppData\Local\Programs\Python\Python311\Lib\site_packages\pydantic\type_adapter.py - 527 - dump_python)
2024-12-10 20:58:19,435 - APP - app_logger - ERROR - MI ERROR: GenericException: {'ret_code': -1, 'ret_txt': "Unable to serialize unknown type: <class 'pyodbc.Row'>"} - ERROR: Unable to serialize unknown type: <class 'pyodbc.Row'> - Unable to serialize unknown type: <class 'pyodbc.Row'> - LOCALIZACION: return self.serializer.to_python( - C:\Users\lvicente\AppData\Local\Programs\Python\Python311\Lib\site_packages\pydantic\type_adapter.py - 527 - dump_python)
2024-12-10 21:14:34,087 - APP - app_logger - ERROR - MI ERROR: GenericException: {'ret_code': -1, 'ret_txt': "Unable to serialize unknown type: <class 'pyodbc.Row'>"} - ERROR: Unable to serialize unknown type: <class 'pyodbc.Row'> - Unable to serialize unknown type: <class 'pyodbc.Row'> - LOCALIZACION: return self.serializer.to_python( - C:\Users\lvicente\AppData\Local\Programs\Python\Python311\Lib\site_packages\pydantic\type_adapter.py - 527 - dump_python)
2024-12-10 21:19:35,358 - APP - app_logger - ERROR - MI ERROR: GenericException: {'ret_code': -1, 'ret_txt': "Unable to serialize unknown type: <class 'pyodbc.Row'>"} - ERROR: Unable to serialize unknown type: <class 'pyodbc.Row'> - Unable to serialize unknown type: <class 'pyodbc.Row'> - LOCALIZACION: return self.serializer.to_python( - C:\Users\lvicente\AppData\Local\Programs\Python\Python311\Lib\site_packages\pydantic\type_adapter.py - 527 - dump_python)
2024-12-10 21:24:08,466 - APP - app_logger - ERROR - MI ERROR: GenericException: {'ret_code': -1, 'ret_txt': "Unable to serialize unknown type: <class 'pyodbc.Row'>"} - ERROR: Unable to serialize unknown type: <class 'pyodbc.Row'> - Unable to serialize unknown type: <class 'pyodbc.Row'> - LOCALIZACION: return self.serializer.to_python( - C:\Users\lvicente\AppData\Local\Programs\Python\Python311\Lib\site_packages\pydantic\type_adapter.py - 527 - dump_python)
2024-12-10 21:26:43,270 - APP - app_logger - ERROR - MI ERROR: GenericException: {'ret_code': -1, 'ret_txt': "Unable to serialize unknown type: <class 'pyodbc.Row'>"} - ERROR: Unable to serialize unknown type: <class 'pyodbc.Row'> - Unable to serialize unknown type: <class 'pyodbc.Row'> - LOCALIZACION: return self.serializer.to_python( - C:\Users\lvicente\AppData\Local\Programs\Python\Python311\Lib\site_packages\pydantic\type_adapter.py - 527 - dump_python)
